Workbook

Sheet Compras
A2: Lista de compras | Protótipo CM5 / RP2040
A3: Bancada térmica e carga elétrica de três diodos • 20 produtos • 60 links • Consulta: 22/10/2026
A4: Quantidades propostas para uma bancada. Altere a quantidade para descontar itens já disponíveis no laboratório. A fonte de bancada está incluída; a ponte H é opcional, com quantidade zero.
A5: O conjunto TEC é uma opção de ensaio. A equivalência com o laser depende do modelo e das especificações térmicas. A placa R6 de controle do MZM mantém seu projeto de alimentação de 15 V.
A6: Subtotal dos itens cotados | D6: =SUM(I10:I29) -> 952.85 | G6: Itens com preço pendente | J6: =COUNTIF(C10:C29,">0")-COUNTIF(I10:I29,">0") -> 1 | K6: Sem frete. Não é um orçamento final.
A7: Azul: quantidade e opção de compra editáveis. Escolha 1, 2 ou 3 para atualizar embalagem e preço. Campo vazio em Preço significa “consultar”; não significa custo zero. Detalhes das ofertas na aba Cotações.
A9: ID | B9: Produto / especificação | C9: Qtd. a comprar | D9: Unidade | E9: Opção 1, 2 ou 3 | F9: Qtd. por lote | G9: Lotes | H9: Preço / lote | I9: Subtotal cotado | J9: Link 1 | K9: Link 2 | L9: Link 3 | M9: Para que serve / critério de escolha
A10: 01 | B10: Raspberry Pi Pico — RP2040 | C10: 2 | D10: placa | E10: 1 | F10: =VLOOKUP($A10&"-"&$E10,'Cotações'!$A$8:$K$67,6,FALSE) -> 1 | G10: =ROUNDUP(C10/F10,0) -> 2 | H10: =IF(VLOOKUP($A10&"-"&$E10,'Cotações'!$A$8:$K$67,7,FALSE)=0,"",VLOOKUP($A10&"-"&$E10,'Cotações'!$A$8:$K$67,7,FALSE)) -> 75.86 | I10: =IF(C10=0,0,IF(H10="","",G10*H10)) -> 151.72 | J10: =IFERROR(HYPERLINK('Cotações'!J8,'Cotações'!D8),'Cotações'!D8) -> RoboBuilders | K10: =IFERROR(HYPERLINK('Cotações'!J9,'Cotações'!D9),'Cotações'!D9) -> Usinainfo | L10: =IFERROR(HYPERLINK('Cotações'!J10,'Cotações'!D10),'Cotações'!D10) -> Proesi | M10: Uma placa ativa e uma reserva. USB alimenta a lógica; não exige fonte externa de 3,3 V. Escolher Pico com RP2040, não Pico 2.
A11: 02 | B11: Conjunto térmico: TEC + dissipador + ventilação | C11: 1 | D11: conjunto | E11: 1 | F11: =VLOOKUP($A11&"-"&$E11,'Cotações'!$A$8:$K$67,6,FALSE) -> 1 | G11: =ROUNDUP(C11/F11,0) -> 1 | H11: =IF(VLOOKUP($A11&"-"&$E11,'Cotações'!$A$8:$K$67,7,FALSE)=0,"",VLOOKUP($A11&"-"&$E11,'Cotações'!$A$8:$K$67,7,FALSE)) -> 102.9 | I11: =IF(C11=0,0,IF(H11="","",G11*H11)) -> 102.9 | J11: =IFERROR(HYPERLINK('Cotações'!J11,'Cotações'!D11),'Cotações'!D11) -> Dissipatec | K11: =IFERROR(HYPERLINK('Cotações'!J12,'Cotações'!D12),'Cotações'!D12) -> TDTEC | L11: =IFERROR(HYPERLINK('Cotações'!J13,'Cotações'!D13),'Cotações'!D13) -> Shopee / Dissipatec | M11: Pastilha TEC1-12706 para bancada didática. O kit reúne TEC, dissipação e ventilação. Não foi comprovada equivalência com o TEC do laser.
A12: 03 | B12: Ponte H BTS7960 — estudo de acionamento | C12: 0 | D12: módulo | E12: 1 | F12: =VLOOKUP($A12&"-"&$E12,'Cotações'!$A$8:$K$67,6,FALSE) -> 1 | G12: =ROUNDUP(C12/F12,0) -> 0 | H12: =IF(VLOOKUP($A12&"-"&$E12,'Cotações'!$A$8:$K$67,7,FALSE)=0,"",VLOOKUP($A12&"-"&$E12,'Cotações'!$A$8:$K$67,7,FALSE)) -> 44.99 | I12: =IF(C12=0,0,IF(H12="","",G12*H12)) -> 0 | J12: =IFERROR(HYPERLINK('Cotações'!J14,'Cotações'!D14),'Cotações'!D14) -> Casa da Robótica | K12: =IFERROR(HYPERLINK('Cotações'!J15,'Cotações'!D15),'Cotações'!D15) -> Vida de Silício | L12: =IFERROR(HYPERLINK('Cotações'!J16,'Cotações'!D16),'Cotações'!D16) -> Saravati | M12: Opcional, fora da compra base. Serve para estudar reversão e potência. Uso com TEC exige projeto do filtro e da malha; não é controlador de laser pronto.
A13: 04 | B13: Sensor NTC 10 kΩ — B3950 | C13: 2 | D13: sensor | E13: 1 | F13: =VLOOKUP($A13&"-"&$E13,'Cotações'!$A$8:$K$67,6,FALSE) -> 1 | G13: =ROUNDUP(C13/F13,0) -> 2 | H13: =IF(VLOOKUP($A13&"-"&$E13,'Cotações'!$A$8:$K$67,7,FALSE)=0,"",VLOOKUP($A13&"-"&$E13,'Cotações'!$A$8:$K$67,7,FALSE)) -> 25.2 | I13: =IF(C13=0,0,IF(H13="","",G13*H13)) -> 50.4 | J13: =IFERROR(HYPERLINK('Cotações'!J17,'Cotações'!D17),'Cotações'!D17) -> Malta Suprimentos | K13: =IFERROR(HYPERLINK('Cotações'!J18,'Cotações'!D18),'Cotações'!D18) -> Easytronics | L13: =IFERROR(HYPERLINK('Cotações'!J19,'Cotações'!D19),'Cotações'!D19) -> Liohm | M13: Um sensor acompanha a carga térmica e outro o dissipador. O formato físico das alternativas muda; prever fixação e bom contato térmico.
A14: 05 | B14: ADC ADS1115 em módulo I²C | C14: 1 | D14: módulo | E14: 1 | F14: =VLOOKUP($A14&"-"&$E14,'Cotações'!$A$8:$K$67,6,FALSE) -> 1 | G14: =ROUNDUP(C14/F14,0) -> 1 | H14: =IF(VLOOKUP($A14&"-"&$E14,'Cotações'!$A$8:$K$67,7,FALSE)=0,"",VLOOKUP($A14&"-"&$E14,'Cotações'!$A$8:$K$67,7,FALSE)) -> 16.2 | I14: =IF(C14=0,0,IF(H14="","",G14*H14)) -> 16.2 | J14: =IFERROR(HYPERLINK('Cotações'!J20,'Cotações'!D20),'Cotações'!D20) -> A2 Robotics | K14: =IFERROR(HYPERLINK('Cotações'!J21,'Cotações'!D21),'Cotações'!D21) -> Ardushop | L14: =IFERROR(HYPERLINK('Cotações'!J22,'Cotações'!D22),'Cotações'!D22) -> Saravati | M14: Lê os divisores dos dois NTCs e a tensão do shunt. Alimentar em 3,3 V e manter os pull-ups I²C em 3,3 V. Não substitui a aquisição do MZM.
A15: 06 | B15: Resistor 10 kΩ, 1%, PTH | C15: 10 | D15: peça | E15: 1 | F15: =VLOOKUP($A15&"-"&$E15,'Cotações'!$A$8:$K$67,6,FALSE) -> 10 | G15: =ROUNDUP(C15/F15,0) -> 1 | H15: =IF(VLOOKUP($A15&"-"&$E15,'Cotações'!$A$8:$K$67,7,FALSE)=0,"",VLOOKUP($A15&"-"&$E15,'Cotações'!$A$8:$K$67,7,FALSE)) -> 0.9 | I15: =IF(C15=0,0,IF(H15="","",G15*H15)) -> 0.9 | J15: =IFERROR(HYPERLINK('Cotações'!J23,'Cotações'!D23),'Cotações'!D23) -> Smart Kits | K15: =IFERROR(HYPERLINK('Cotações'!J24,'Cotações'!D24),'Cotações'!D24) -> Proesi | L15: =IFERROR(HYPERLINK('Cotações'!J25,'Cotações'!D25),'Cotações'!D25) -> Achei Componentes | M15: Dois resistores formam os divisores de tensão dos NTCs; o restante fica de reserva. Aceitar potência de 1/4 W ou superior.
A16: 07 | B16: Capacitor cerâmico 100 nF, 50 V, PTH | C16: 10 | D16: peça | E16: 1 | F16: =VLOOKUP($A16&"-"&$E16,'Cotações'!$A$8:$K$67,6,FALSE) -> 10 | G16: =ROUNDUP(C16/F16,0) -> 1 | H16: =IF(VLOOKUP($A16&"-"&$E16,'Cotações'!$A$8:$K$67,7,FALSE)=0,"",VLOOKUP($A16&"-"&$E16,'Cotações'!$A$8:$K$67,7,FALSE)) -> 1.9 | I16: =IF(C16=0,0,IF(H16="","",G16*H16)) -> 1.9 | J16: =IFERROR(HYPERLINK('Cotações'!J26,'Cotações'!D26),'Cotações'!D26) -> Achei Componentes | K16: =IFERROR(HYPERLINK('Cotações'!J27,'Cotações'!D27),'Cotações'!D27) -> Eletrogate | L16: =IFERROR(HYPERLINK('Cotações'!J28,'Cotações'!D28),'Cotações'!D28) -> MakerHero | M16: Desacoplamento e filtragem local da parte de medição. Pacote inclui reserva. Não é o filtro de potência de uma ponte H para TEC.
A17: 08 | B17: Aquecedor resistivo: 10 Ω, 20 W | C17: 1 | D17: resistor | E17: 1 | F17: =VLOOKUP($A17&"-"&$E17,'Cotações'!$A$8:$K$67,6,FALSE) -> 1 | G17: =ROUNDUP(C17/F17,0) -> 1 | H17: =IF(VLOOKUP($A17&"-"&$E17,'Cotações'!$A$8:$K$67,7,FALSE)=0,"",VLOOKUP($A17&"-"&$E17,'Cotações'!$A$8:$K$67,7,FALSE)) | I17: =IF(C17=0,0,IF(H17="","",G17*H17)) | J17: =IFERROR(HYPERLINK('Cotações'!J29,'Cotações'!D29),'Cotações'!D29) -> Proesi | K17: =IFERROR(HYPERLINK('Cotações'!J30,'Cotações'!D30),'Cotações'!D30) -> Equitronic | L17: =IFERROR(HYPERLINK('Cotações'!J31,'Cotações'!D31),'Cotações'!D31) -> Mercado Livre | M17: Produz calor para imitar a dissipação do laser. Ensaio inicial proposto: 5 V, 0,5 A e 2,5 W calculados. Fixar à carga com isolamento elétrico.
A18: 09 | B18: Módulo MOSFET D4184 com entrada 3,3 V | C18: 1 | D18: módulo | E18: 1 | F18: =VLOOKUP($A18&"-"&$E18,'Cotações'!$A$8:$K$67,6,FALSE) -> 1 | G18: =ROUNDUP(C18/F18,0) -> 1 | H18: =IF(VLOOKUP($A18&"-"&$E18,'Cotações'!$A$8:$K$67,7,FALSE)=0,"",VLOOKUP($A18&"-"&$E18,'Cotações'!$A$8:$K$67,7,FALSE)) -> 8.5 | I18: =IF(C18=0,0,IF(H18="","",G18*H18)) -> 8.5 | J18: =IFERROR(HYPERLINK('Cotações'!J32,'Cotações'!D32),'Cotações'!D32) -> Só Tudo | K18: =IFERROR(HYPERLINK('Cotações'!J33,'Cotações'!D33),'Cotações'!D33) -> Curto Circuito | L18: =IFERROR(HYPERLINK('Cotações'!J34,'Cotações'!D34),'Cotações'!D34) -> AutoCore Robótica | M18: Controla por PWM a potência do aquecedor. Escolher a versão de comando 3,3–20 V; há módulos optoacoplados semelhantes que exigem 5 V.
A19: 10 | B19: Diodo 1N5408 — carga de três diodos | C19: 6 | D19: diodo | E19: 1 | F19: =VLOOKUP($A19&"-"&$E19,'Cotações'!$A$8:$K$67,6,FALSE) -> 10 | G19: =ROUNDUP(C19/F19,0) -> 1 | H19: =IF(VLOOKUP($A19&"-"&$E19,'Cotações'!$A$8:$K$67,7,FALSE)=0,"",VLOOKUP($A19&"-"&$E19,'Cotações'!$A$8:$K$67,7,FALSE)) -> 7.9 | I19: =IF(C19=0,0,IF(H19="","",G19*H19)) -> 7.9 | J19: =IFERROR(HYPERLINK('Cotações'!J35,'Cotações'!D35),'Cotações'!D35) -> Eletrogate | K19: =IFERROR(HYPERLINK('Cotações'!J36,'Cotações'!D36),'Cotações'!D36) -> Baú da Eletrônica | L19: =IFERROR(HYPERLINK('Cotações'!J37,'Cotações'!D37),'Cotações'!D37) -> A2 Robotics | M19: Três diodos em série formam a carga elétrica; três são reserva. A carga não produz luz nem reproduz a curva óptica do laser.
A20: 11 | B20: Resistor shunt de 1 Ω, 5 W | C20: 2 | D20: resistor | E20: 1 | F20: =VLOOKUP($A20&"-"&$E20,'Cotações'!$A$8:$K$67,6,FALSE) -> 1 | G20: =ROUNDUP(C20/F20,0) -> 2 | H20: =IF(VLOOKUP($A20&"-"&$E20,'Cotações'!$A$8:$K$67,7,FALSE)=0,"",VLOOKUP($A20&"-"&$E20,'Cotações'!$A$8:$K$67,7,FALSE)) -> 1.76 | I20: =IF(C20=0,0,IF(H20="","",G20*H20)) -> 3.52 | J20: =IFERROR(HYPERLINK('Cotações'!J38,'Cotações'!D38),'Cotações'!D38) -> Achei Componentes | K20: =IFERROR(HYPERLINK('Cotações'!J39,'Cotações'!D39),'Cotações'!D39) -> RS Componentes | L20: =IFERROR(HYPERLINK('Cotações'!J40,'Cotações'!D40),'Cotações'!D40) -> Intertronix | M20: Um shunt no retorno da carga permite calcular I = V/R; outro fica de reserva. A tolerância de 5% limita a exatidão sem caracterização do valor real.
A21: 12 | B21: XL4015 com ajuste de tensão E corrente | C21: 3 | D21: módulo | E21: 1 | F21: =VLOOKUP($A21&"-"&$E21,'Cotações'!$A$8:$K$67,6,FALSE) -> 1 | G21: =ROUNDUP(C21/F21,0) -> 3 | H21: =IF(VLOOKUP($A21&"-"&$E21,'Cotações'!$A$8:$K$67,7,FALSE)=0,"",VLOOKUP($A21&"-"&$E21,'Cotações'!$A$8:$K$67,7,FALSE)) -> 16.99 | I21: =IF(C21=0,0,IF(H21="","",G21*H21)) -> 50.97 | J21: =IFERROR(HYPERLINK('Cotações'!J41,'Cotações'!D41),'Cotações'!D41) -> Casa da Robótica | K21: =IFERROR(HYPERLINK('Cotações'!J42,'Cotações'!D42),'Cotações'!D42) -> Usinainfo | L21: =IFERROR(HYPERLINK('Cotações'!J43,'Cotações'!D43),'Cotações'!D43) -> Eletrogate | M21: Três ramos: TEC com ajuste DC manual; aquecedor em 5 V; carga de diodos com corrente limitada. Comprar versão CC/CV, não módulo de um só trimpot.
A22: 13 | B22: Fonte de bancada ajustável 0–30 V / 5 A | C22: 1 | D22: fonte | E22: 1 | F22: =VLOOKUP($A22&"-"&$E22,'Cotações'!$A$8:$K$67,6,FALSE) -> 1 | G22: =ROUNDUP(C22/F22,0) -> 1 | H22: =IF(VLOOKUP($A22&"-"&$E22,'Cotações'!$A$8:$K$67,7,FALSE)=0,"",VLOOKUP($A22&"-"&$E22,'Cotações'!$A$8:$K$67,7,FALSE)) -> 410 | I22: =IF(C22=0,0,IF(H22="","",G22*H22)) -> 410 | J22: =IFERROR(HYPERLINK('Cotações'!J44,'Cotações'!D44),'Cotações'!D44) -> TEC BIG / Sunshine | K22: =IFERROR(HYPERLINK('Cotações'!J45,'Cotações'!D45),'Cotações'!D45) -> RF4 Ferramentas | L22: =IFERROR(HYPERLINK('Cotações'!J46,'Cotações'!D46),'Cotações'!D46) -> Shopee / Yaxun | M22: Alimenta o ensaio em 12 V com limitação de corrente. Excluir da compra se o laboratório já tiver uma. Não representa operação do TEC em sua potência máxima.
A23: 14 | B23: Protoboard 830 pontos | C23: 1 | D23: placa | E23: 1 | F23: =VLOOKUP($A23&"-"&$E23,'Cotações'!$A$8:$K$67,6,FALSE) -> 1 | G23: =ROUNDUP(C23/F23,0) -> 1 | H23: =IF(VLOOKUP($A23&"-"&$E23,'Cotações'!$A$8:$K$67,7,FALSE)=0,"",VLOOKUP($A23&"-"&$E23,'Cotações'!$A$8:$K$67,7,FALSE)) -> 11.99 | I23: =IF(C23=0,0,IF(H23="","",G23*H23)) -> 11.99 | J23: =IFERROR(HYPERLINK('Cotações'!J47,'Cotações'!D47),'Cotações'!D47) -> Casa da Robótica | K23: =IFERROR(HYPERLINK('Cotações'!J48,'Cotações'!D48),'Cotações'!D48) -> Eletrogate | L23: =IFERROR(HYPERLINK('Cotações'!J49,'Cotações'!D49),'Cotações'!D49) -> Mult Comercial | M23: Montagem dos NTCs, divisores e sinais de baixa corrente. TEC, aquecedor e corrente dos diodos devem usar conexões soldadas ou bornes apropriados.
A24: 15 | B24: Kit de jumpers MM + MF + FF | C24: 1 | D24: kit | E24: 1 | F24: =VLOOKUP($A24&"-"&$E24,'Cotações'!$A$8:$K$67,6,FALSE) -> 1 | G24: =ROUNDUP(C24/F24,0) -> 1 | H24: =IF(VLOOKUP($A24&"-"&$E24,'Cotações'!$A$8:$K$67,7,FALSE)=0,"",VLOOKUP($A24&"-"&$E24,'Cotações'!$A$8:$K$67,7,FALSE)) -> 22.9 | I24: =IF(C24=0,0,IF(H24="","",G24*H24)) -> 22.9 | J24: =IFERROR(HYPERLINK('Cotações'!J50,'Cotações'!D50),'Cotações'!D50) -> MakerHero | K24: =IFERROR(HYPERLINK('Cotações'!J51,'Cotações'!D51),'Cotações'!D51) -> Casa da Robótica | L24: =IFERROR(HYPERLINK('Cotações'!J52,'Cotações'!D52),'Cotações'!D52) -> Shopee | M24: Ligações dos sinais entre Pico, ADC e módulos. Apenas sinais e baixa corrente; não usar jumpers Dupont nos ramos de potência.
A25: 16 | B25: Cabo USB-A → micro-USB com dados | C25: 2 | D25: cabo | E25: 1 | F25: =VLOOKUP($A25&"-"&$E25,'Cotações'!$A$8:$K$67,6,FALSE) -> 1 | G25: =ROUNDUP(C25/F25,0) -> 2 | H25: =IF(VLOOKUP($A25&"-"&$E25,'Cotações'!$A$8:$K$67,7,FALSE)=0,"",VLOOKUP($A25&"-"&$E25,'Cotações'!$A$8:$K$67,7,FALSE)) -> 9.9 | I25: =IF(C25=0,0,IF(H25="","",G25*H25)) -> 19.8 | J25: =IFERROR(HYPERLINK('Cotações'!J53,'Cotações'!D53),'Cotações'!D53) -> AutoCore Robótica | K25: =IFERROR(HYPERLINK('Cotações'!J54,'Cotações'!D54),'Cotações'!D54) -> Eletrogate | L25: =IFERROR(HYPERLINK('Cotações'!J55,'Cotações'!D55),'Cotações'!D55) -> RoboCore | M25: Programação e alimentação das duas Pico. Se a placa adquirida tiver USB-C, o cabo precisa acompanhar essa versão.
A26: 17 | B26: Barra de pinos macho 1 × 40; 2,54 mm | C26: 3 | D26: barra | E26: 1 | F26: =VLOOKUP($A26&"-"&$E26,'Cotações'!$A$8:$K$67,6,FALSE) -> 1 | G26: =ROUNDUP(C26/F26,0) -> 3 | H26: =IF(VLOOKUP($A26&"-"&$E26,'Cotações'!$A$8:$K$67,7,FALSE)=0,"",VLOOKUP($A26&"-"&$E26,'Cotações'!$A$8:$K$67,7,FALSE)) -> 0.8 | I26: =IF(C26=0,0,IF(H26="","",G26*H26)) -> 2.4 | J26: =IFERROR(HYPERLINK('Cotações'!J56,'Cotações'!D56),'Cotações'!D56) -> Eletrogate | K26: =IFERROR(HYPERLINK('Cotações'!J57,'Cotações'!D57),'Cotações'!D57) -> Mult Comercial | L26: =IFERROR(HYPERLINK('Cotações'!J58,'Cotações'!D58),'Cotações'!D58) -> Usinainfo | M26: Duas barras atendem duas Pico sem pinos soldados; a terceira é reserva para o ADC. Dividir cada barra em duas de 20 pinos para uma Pico.
A27: 18 | B27: Fio de cobre flexível 18 AWG, vermelho/preto | C27: 2 | D27: m total | E27: 1 | F27: =VLOOKUP($A27&"-"&$E27,'Cotações'!$A$8:$K$67,6,FALSE) -> 4 | G27: =ROUNDUP(C27/F27,0) -> 1 | H27: =IF(VLOOKUP($A27&"-"&$E27,'Cotações'!$A$8:$K$67,7,FALSE)=0,"",VLOOKUP($A27&"-"&$E27,'Cotações'!$A$8:$K$67,7,FALSE)) -> 84.9 | I27: =IF(C27=0,0,IF(H27="","",G27*H27)) -> 84.9 | J27: =IFERROR(HYPERLINK('Cotações'!J59,'Cotações'!D59),'Cotações'!D59) -> Azupa | K27: =IFERROR(HYPERLINK('Cotações'!J60,'Cotações'!D60),'Cotações'!D60) -> Action Modelismo | L27: =IFERROR(HYPERLINK('Cotações'!J61,'Cotações'!D61),'Cotações'!D61) -> Shopee | M27: Previsão mínima de 1 m por cor para os ramos de baixa tensão. As ofertas têm comprimentos diferentes; cálculo considera metros totais.
A28: 19 | B28: Porta-fusível de fio, 5 × 20 mm | C28: 2 | D28: peça | E28: 1 | F28: =VLOOKUP($A28&"-"&$E28,'Cotações'!$A$8:$K$67,6,FALSE) -> 1 | G28: =ROUNDUP(C28/F28,0) -> 2 | H28: =IF(VLOOKUP($A28&"-"&$E28,'Cotações'!$A$8:$K$67,7,FALSE)=0,"",VLOOKUP($A28&"-"&$E28,'Cotações'!$A$8:$K$67,7,FALSE)) -> 1.9 | I28: =IF(C28=0,0,IF(H28="","",G28*H28)) -> 3.8 | J28: =IFERROR(HYPERLINK('Cotações'!J62,'Cotações'!D62),'Cotações'!D62) -> Eletrogate | K28: =IFERROR(HYPERLINK('Cotações'!J63,'Cotações'!D63),'Cotações'!D63) -> Baú da Eletrônica | L28: =IFERROR(HYPERLINK('Cotações'!J64,'Cotações'!D64),'Cotações'!D64) -> AutoCore Robótica | M28: Proteção em série com os ramos de potência do protótipo. Usar porta-fusível isolado; não é componente para inserir na protoboard.
A29: 20 | B29: Fusível rápido 3 A, 5 × 20 mm | C29: 5 | D29: peça | E29: 1 | F29: =VLOOKUP($A29&"-"&$E29,'Cotações'!$A$8:$K$67,6,FALSE) -> 1 | G29: =ROUNDUP(C29/F29,0) -> 5 | H29: =IF(VLOOKUP($A29&"-"&$E29,'Cotações'!$A$8:$K$67,7,FALSE)=0,"",VLOOKUP($A29&"-"&$E29,'Cotações'!$A$8:$K$67,7,FALSE)) -> 0.43 | I29: =IF(C29=0,0,IF(H29="","",G29*H29)) -> 2.15 | J29: =IFERROR(HYPERLINK('Cotações'!J65,'Cotações'!D65),'Cotações'!D65) -> Plenobras | K29: =IFERROR(HYPERLINK('Cotações'!J66,'Cotações'!D66),'Cotações'!D66) -> Proesi | L29: =IFERROR(HYPERLINK('Cotações'!J67,'Cotações'!D67),'Cotações'!D67) -> Dimensional | M29: Dois em uso e três reservas para ensaios com corrente limitada. Valor preliminar dos ramos; não permite explorar 6 A do TEC. Confirmar aplicação em CC.
A31: Compra inicial: a ponte H (03) está excluída. O TEC é acionado em corrente contínua com ajuste manual no XL4015; a malha automática do TEC ainda requer um driver e filtro dimensionados para o laser.
A32: Como comparar: cada linha usa apenas uma oferta. A quantidade de lotes é arredondada para cima. Exemplo: 6 diodos necessários e pacote de 10 → comprar 1 pacote. Não somar os três fornecedores.
A33: Aba Uso e critérios: sequência dos ensaios, alimentação, distinção entre carga elétrica e térmica, limites do conjunto proposto e fontes técnicas.

Sheet Cotações
A2: Cotações e links de origem
A3: Três links de produto por item. As embalagens, formas físicas e condições comerciais podem variar. Pesquisa consultada em 22/10/2026.
A4: Preços em reais, sem frete e sem desconto Pix no cálculo. Atualize preço e quantidade do lote somente após conferir a opção escolhida. Ofertas indisponíveis foram identificadas; não são recomendadas para compra imediata.
A5: “A confirmar” indica que a disponibilidade não foi comprovada. Uma página localizada pelo buscador não comprova estoque. Na lista principal, a opção 1 é a referência de orçamento, não uma garantia de menor preço.
A7: Chave | B7: ID | C7: Opção | D7: Fornecedor / canal | E7: Produto e embalagem | F7: Unidades / lote | G7: Preço / lote (R$) | H7: Condição do preço | I7: Disponibilidade observada | J7: URL de origem | K7: Observação da oferta
A8: 01-1 | B8: 01 | C8: 1 | D8: RoboBuilders | E8: 1 placa Pico / RP2040 | F8: 1 | G8: 75.86 | H8: Preço normal anunciado | I8: Disponível na página | J8: https://www.robobuilders.com.br/placa-raspberry-pi-pico-rp2040-arm-cortex-133mhz-256kb | K8: Preço normal. Descrição da loja contém erros de memória; usar documentação oficial para especificações.
A9: 01-2 | B9: 01 | C9: 2 | D9: Usinainfo | E9: 1 placa Pico / RP2040 | F9: 1 | G9: 76.4 | H9: Preço normal anunciado | I9: Indisponível na página | J9: https://www.usinainfo.com.br/placa-raspberry-pi/raspberry-pi-pico-rp2040-com-micro-usb-8372.html | K9: Preço normal exibido; página oferece aviso de reposição.
A10: 01-3 | B10: 01 | C10: 3 | D10: Proesi | E10: 1 placa Pico / RP2040 | F10: 1 | H10: Não confirmado | I10: A confirmar | J10: https://www.proesi.com.br/raspberry-pi-pico-rp2040-2mb-original | K10: Produto localizado na pesquisa; acesso direto bloqueado (403).
A11: 02-1 | B11: 02 | C11: 1 | D11: Dissipatec | E11: 1 conjunto; TEC1-12706; cooler duplo; 12 V | F11: 1 | G11: 102.9 | H11: Preço normal anunciado | I11: Disponível em 2 dias úteis | J11: https://www.dissipatec.com.br/dissipadores-termoeletrico/dissipadores-termoeletrico/dissipador-termoeletrico-cooler-duplo-peltier-12v | K11: Preço normal anunciado. Modelo DT104 P; capacidade térmica depende da montagem.
A12: 02-2 | B12: 02 | C12: 2 | D12: TDTEC | E12: 1 conjunto; TEC12706; dissipador; fan 80 mm; pasta e fixadores | F12: 1 | H12: Não confirmado | I12: Indisponível na página | J12: https://www.tdtec.com.br/eletronicos/kit-refrigeracao-12v-peltier-12706-dissipador-cooler | K12: Kit com uma ventoinha; geometria diferente da opção 1.
A13: 02-3 | B13: 02 | C13: 3 | D13: Shopee / Dissipatec | E13: 1 kit; TEC12706 + dissipador + cooler | F13: 1 | G13: 154 | H13: Preço normal anunciado | I13: A confirmar | J13: https://shopee.com.br/Kit-Refrigera%C3%A7%C3%A3o-12v-Peltier-12706-Dissipador-Cooler-i.369065757.18761286023 | K13: Preço normal; Pix exibido R$ 146,30. Mesmo vendedor da opção 1, em outro canal; kit pode diferir.
A14: 03-1 | B14: 03 | C14: 1 | D14: Casa da Robótica | E14: 1 módulo BTS7960 / IBT-2 | F14: 1 | G14: 44.99 | H14: Preço normal anunciado | I14: Disponível na página | J14: https://www.casadarobotica.com/sensores-modulos/modulos/outros/modulo-driver-ponte-h-43a-bts7960 | K14: Anúncio refere-se a driver de motor. Corrente comercial de 43 A não é corrente contínua garantida da montagem.
A15: 03-2 | B15: 03 | C15: 2 | D15: Vida de Silício | E15: 1 módulo BTS7960 | F15: 1 | G15: 39.9 | H15: Preço normal anunciado | I15: Indisponível na página | J15: https://vidadesilicio.com.br/produto/modulo-driver-ponte-h-bts7960-43a/ | K15: Preço anunciado; fora de estoque.
A16: 03-3 | B16: 03 | C16: 3 | D16: Saravati | E16: 1 módulo BTS7960 | F16: 1 | H16: Não confirmado | I16: A confirmar | J16: https://www.saravati.com.br/modulo-driver-ponte-h-bts7960.html | K16: Produto localizado; acesso direto bloqueado (403).
A17: 04-1 | B17: 04 | C17: 1 | D17: Malta Suprimentos | E17: 1 sonda inox 5 × 25 mm; 10 kΩ; 1%; STB3950 | F17: 1 | G17: 25.2 | H17: Preço normal anunciado | I17: Disponível na página | J17: https://www.maltasuprimentos.com.br/sensor-de-temperatura-ntc-10k-1-5x25mm-inox-msa-stb3950 | K17: Preço normal; Pix R$ 23,94. Fixação da sonda difere de um sensor de olhal.
A18: 04-2 | B18: 04 | C18: 2 | D18: Easytronics | E18: 1 NTC 10 kΩ / B3950; olhal 5 mm | F18: 1 | H18: Não confirmado | I18: A confirmar | J18: https://www.easytronics.com.br/sensor-de-temperatura-termistor-ntc-10k-b3950-olhal-5mm | K18: Produto localizado; acesso direto bloqueado (403).
A19: 04-3 | B19: 04 | C19: 3 | D19: Liohm | E19: 1 NTC 10 kΩ / B3950; olhal 3 mm; cabo 1,5 m | F19: 1 | G19: 45 | H19: Preço normal anunciado | I19: A confirmar | J19: https://loja.liohm.com.br/produtos/sensor-ntc-10k-olhal-furo-3-mm-cabo-pp-2x26-awg-1500-mm/ | K19: Preço exibido; disponibilidade não inequívoca no conteúdo consultado.
A20: 05-1 | B20: 05 | C20: 1 | D20: A2 Robotics | E20: 1 módulo ADS1115; 4 entradas multiplexadas | F20: 1 | G20: 16.2 | H20: Preço normal anunciado | I20: Disponível na página | J20: https://www.a2robotics.com.br/modulo-conversor-analogico-adc-ads1115 | K20: Preço normal; Pix R$ 15,39.
A21: 05-2 | B21: 05 | C21: 2 | D21: Ardushop | E21: 1 módulo ADS1115 | F21: 1 | H21: Não confirmado | I21: A confirmar | J21: https://www.ardushop.com.br/modulo-conversor-analogico-digital-ads1115-16bits-4-canais | K21: Página consultada; preço não consolidado.
A22: 05-3 | B22: 05 | C22: 3 | D22: Saravati | E22: 1 módulo ADS1115 | F22: 1 | H22: Não confirmado | I22: A confirmar | J22: https://www.saravati.com.br/modulo-conversor-analogico-digital-ads1115.html | K22: Produto localizado; acesso direto bloqueado (403).
A23: 06-1 | B23: 06 | C23: 1 | D23: Smart Kits | E23: Pacote com 10 resistores; 1/4 W; 1% | F23: 10 | G23: 0.9 | H23: Preço normal anunciado | I23: Compra habilitada na página | J23: https://www.smartkits.com.br/resistor-10k-14w-1-10-unidades | K23: Preço do pacote, não de cada resistor.
A24: 06-2 | B24: 06 | C24: 2 | D24: Proesi | E24: 1 resistor; 1/4 W; 1% | F24: 1 | H24: Não confirmado | I24: A confirmar | J24: https://www.proesi.com.br/resistor-precisao-1-1-4w-10k | K24: Link localizado; preço e estoque não confirmados.
A25: 06-3 | B25: 06 | C25: 3 | D25: Achei Componentes | E25: Pacote com 10 resistores; 0,6 W; 1% | F25: 10 | H25: Não confirmado | I25: A confirmar | J25: https://www.acheicomponentes.com.br/resistor/kit-10-pecas-resistor-10k-1-0-6w-axial | K25: Link localizado; preço e estoque não confirmados.
A26: 07-1 | B26: 07 | C26: 1 | D26: Achei Componentes | E26: Pacote com 10 capacitores; disco; marcação 104 | F26: 10 | G26: 1.9 | H26: Preço normal anunciado | I26: Disponível na página | J26: https://www.acheicomponentes.com.br/capacitores/kit-10-pecas-capacitor-ceramico-disco-100nf-100k-50v-104 | K26: Preço do pacote. 100 nF = 0,1 µF.
A27: 07-2 | B27: 07 | C27: 2 | D27: Eletrogate | E27: 1 capacitor cerâmico 100 nF / 50 V | F27: 1 | H27: Não confirmado | I27: A confirmar | J27: https://www.eletrogate.com/capacitor-disco-ceramico-100nf-x-50v | K27: Página consultada; preço do item não apareceu no conteúdo retornado.
A28: 07-3 | B28: 07 | C28: 3 | D28: MakerHero | E28: 1 capacitor cerâmico 100 nF / 50 V | F28: 1 | H28: Não confirmado | I28: A confirmar | J28: https://www.makerhero.com/produto/capacitor-ceramico-100nf-50v/ | K28: Link localizado; preço e estoque não confirmados.
A29: 08-1 | B29: 08 | C29: 1 | D29: Proesi | E29: 1 resistor de porcelana; 10 Ω / 20 W | F29: 1 | H29: Não confirmado | I29: A confirmar | J29: https://www.proesi.com.br/resistor-de-porcelana-20w-10r | K29: Especificação confirmada na página; preço não exibido.
A30: 08-2 | B30: 08 | C30: 2 | D30: Equitronic | E30: 1 resistor de fio axial; 10 Ω / 20 W; 9 × 53 mm | F30: 1 | H30: Não confirmado | I30: A confirmar | J30: https://loja.equitronic.com.br/componentes-eletronicos/resistor/10w/resistor-20w-10r-fio-knp-9x53mm | K30: Formato diferente da opção 1; acesso direto bloqueado (403).
A31: 08-3 | B31: 08 | C31: 3 | D31: Mercado Livre | E31: Pacote com 4 resistores de porcelana; 10 Ω / 20 W | F31: 4 | H31: Não confirmado | I31: A confirmar | J31: https://www.mercadolivre.com.br/kit-04-resistor-porcelana-20w-10r-5-mr4352/up/MLBU1155701161 | K31: Link localizado; preço e estoque não confirmados.
A32: 09-1 | B32: 09 | C32: 1 | D32: Só Tudo | E32: 1 módulo D4184; potência 5–36 V; comando 3,3–20 V | F32: 1 | G32: 8.5 | H32: Preço normal anunciado | I32: Entrega imediata | J32: https://www.sotudo.com.br/produto/modulo-controlador-pwm-de-alta-potencia-d4184 | K32: Preço anunciado. Dimensionamento proposto para aquecedor de 0,5 A; não usar 30 A/400 W como garantia da placa.
A33: 09-2 | B33: 09 | C33: 2 | D33: Curto Circuito | E33: 1 módulo D4184 duplo; lógica 3,3–20 V | F33: 1 | H33: Não confirmado | I33: A confirmar | J33: https://curtocircuito.com.br/modulo-mosfet-duplo-40v-50a-400w-d4184.html | K33: Página consultada. Conferir disponibilidade da versão de dois MOSFETs.
A34: 09-3 | B34: 09 | C34: 3 | D34: AutoCore Robótica | E34: 1 módulo D4184; lógica 3,3–20 V | F34: 1 | H34: Não confirmado | I34: A confirmar | J34: https://www.autocorerobotica.com.br/modulo-controlador-pwm-d4184-30a-400w-36v | K34: Especificação do sinal de comando localizada; preço não consolidado.
A35: 10-1 | B35: 10 | C35: 1 | D35: Eletrogate | E35: Pacote com 10 diodos 1N5408 | F35: 10 | G35: 7.9 | H35: Preço normal anunciado | I35: Disponível na página | J35: https://www.eletrogate.com/diodo-1n5408 | K35: O orçamento inclui um pacote de 10, apesar de a necessidade ser 6.
A36: 10-2 | B36: 10 | C36: 2 | D36: Baú da Eletrônica | E36: 1 diodo 1N5408 | F36: 1 | H36: Não confirmado | I36: A confirmar | J36: https://www.baudaeletronica.com.br/produto/diodo-1n5408.html | K36: Link localizado; preço e estoque não confirmados.
A37: 10-3 | B37: 10 | C37: 3 | D37: A2 Robotics | E37: Pacote com 10 diodos 1N5408 | F37: 10 | H37: Não confirmado | I37: A confirmar | J37: https://www.a2robotics.com.br/diodo-1n5408 | K37: Link localizado; preço e estoque não confirmados.
A38: 11-1 | B38: 11 | C38: 1 | D38: Achei Componentes | E38: 1 resistor axial; 1 Ω / 5 W / 5% | F38: 1 | G38: 1.76 | H38: Preço normal anunciado | I38: Disponível na página | J38: https://www.acheicomponentes.com.br/resistor/resistor-5w/resistor-1r-5w-5-axial | K38: Preço unitário.
A39: 11-2 | B39: 11 | C39: 2 | D39: RS Componentes | E39: 1 resistor de fio; 1 Ω / 5 W / 5% | F39: 1 | H39: Não confirmado | I39: A confirmar | J39: https://www.rscomponentes.com/resistor-fio-5w-1r-5-knp-fita-acel | K39: Página consultada; preço não consolidado.
A40: 11-3 | B40: 11 | C40: 3 | D40: Intertronix | E40: 1 resistor; 1 Ω / 5 W | F40: 1 | H40: Não confirmado | I40: A confirmar | J40: https://www.intertronix.com.br/produtos/resistor-1r-5w-mrptdrdr/ | K40: Página consultada; preço não consolidado.
A41: 12-1 | B41: 12 | C41: 1 | D41: Casa da Robótica | E41: 1 XL4015 CC/CV com ajustes independentes | F41: 1 | G41: 16.99 | H41: Preço normal anunciado | I41: Disponível na página | J41: https://www.casadarobotica.com/fonte-e-conversores/fontes/reguladores-de-tensao/regulador-com-ajuste-de-corrente-e-tensao-xl4015-5a-dc-dc | K41: Preço normal; Pix/à vista R$ 16,14. Não dimensionar operação contínua pela corrente de pico anunciada.
A42: 12-2 | B42: 12 | C42: 2 | D42: Usinainfo | E42: 1 XL4015 CC/CV; anúncio indica 0,2–3 A | F42: 1 | H42: Não confirmado | I42: A confirmar | J42: https://www.usinainfo.com.br/regulador-de-tensao/regulador-de-tensao-e-corrente-ajustavel-xl4015-dc-step-down-saida-125-a-32vdc-02-a-3a-5880.html | K42: Link localizado; preço e estoque não confirmados.
...

Sheet Uso e critérios
A2: Como esta lista atende ao protótipo
A3: Proposta de bancada auxiliar ao projeto CM5 / RP2040 / MZM • 22/10/2026
A4: Equipe: Carlos Renan Correia Fidelis; Carlos Elias Fialho de Lima; Pablo Daniel Nascimento Vieira.
A5: Tema | B5: Aplicação e decisão de compra
A6: Escopo desta compra | B6: Atende à solicitação de microcontroladores, TEC com dissipação e acionamento, sensor com condicionamento, aquecedor e carga de três diodos. É uma bancada para estudar os circuitos antes de conectar um laser. Não é a lista completa de fabricação da placa R6 nem uma afirmação de que ela já contém controle de corrente do laser e de temperatura.
A7: Microcontrolador auxiliar | B7: A opção mantém a Raspberry Pi Pico com RP2040, já usada no projeto. Uma placa executa aquisição e comando do aquecedor; a segunda é reserva. As quantidades podem ser reduzidas conforme o material disponível. O CM5 pode receber dados posteriormente; não é necessário comprar outro CM5 para começar os ensaios pela USB do computador.
A8: Alimentação do ensaio | B8: Usar a fonte ajustável inicialmente em 12 V, com limitação de corrente. Os três XL4015 separam os ajustes do TEC, do aquecedor e da carga de diodos. A Pico recebe alimentação USB e fornece 3,3 V à parte de medição, dentro da capacidade disponível. Não aplicar 12 V ou 15 V aos GPIOs, ao ADC, à USB ou ao pino 3V3 da Pico.
A9: Conjunto térmico | B9: O TEC transfere calor da carga para o dissipador. A ventoinha ajuda o dissipador a liberar esse calor para o ar. A potência que precisa ser dissipada inclui o calor removido e a potência elétrica consumida pelo TEC. O código TEC1-12706 e o tamanho de 40 × 40 mm não comprovam equivalência com o TEC do laser. As três alternativas de kit têm diferenças mecânicas.
A10: Acionamento inicial do TEC | B10: A proposta base é começar com alimentação DC ajustável manualmente pelo XL4015 CC/CV, sem ponte H. Limitar inicialmente a corrente do ramo a até 2 A e acompanhar a temperatura do dissipador; esse limite é uma condição de ensaio proposta, não uma especificação do laser. A fonte de 5 A e os fusíveis de 3 A não foram dimensionados para explorar a corrente máxima anunciada de 6 A do TEC.
A11: Controle automático do TEC | B11: O BTS7960 foi deixado com quantidade zero, como alternativa para estudo. Um driver de motor não equivale a um controlador TEC de precisão. A passagem para controle automático requer dimensionamento da etapa de potência, filtragem, medição de corrente e malha de temperatura. PWM sem filtragem não foi adotado como solução final do TEC; o guia da Coherent discute ondulação e filtragem na alimentação.
A12: Sensor e condicionamento | B12: Para cada NTC, a proposta é um divisor com resistor de 10 kΩ, alimentado em 3,3 V: resistor fixo no ramo superior e NTC no inferior. A tensão no ponto central diminui quando o NTC aquece. O ADC mede essa tensão; o firmware converte resistência em temperatura usando os parâmetros corretos do sensor. Os capacitores de 100 nF auxiliam a filtragem e o desacoplamento.
A13: Leitura pelo ADS1115 | B13: O ADS1115 permite quatro entradas multiplexadas e comunicação I²C. Pode-se reservar duas entradas para os NTCs e um par diferencial para o shunt, lidos em sequência. Alimentação e pull-ups em 3,3 V mantêm os sinais compatíveis com a Pico. Cada entrada deve permanecer dentro dos limites do ADC; selecionar uma escala de ganho maior não autoriza tensão acima da alimentação. Não se trata de quatro amostragens simultâneas.
A14: Aquecedor que imita o laser | B14: O resistor de 10 Ω transforma energia elétrica em calor. Em 5 V, os valores nominais calculados são I = 5/10 = 0,5 A e P = 5²/10 = 2,5 W. A indicação 20 W é a potência nominal do componente sob suas condições de uso, não o consumo obrigatório. O MOSFET controla a potência média por PWM. Fixar o aquecedor à massa térmica do ensaio com isolamento elétrico apropriado.
A15: Carga de três diodos | B15: Ligar três 1N5408 em série forma uma carga para estudar o fornecimento de corrente. O XL4015 CC/CV permite um primeiro ajuste manual. Propõe-se começar em 0,2 A, valor de ensaio e não corrente nominal do laser. A queda nos diodos varia com corrente e temperatura. A carga não reproduz luz, eficiência óptica ou todos os transientes de um laser; um módulo CC/CV genérico não é um driver aprovado para o laser real.
A16: Ponto de medição de corrente | B16: Com um shunt de 1 Ω, I = Vshunt / 1 Ω. Em 0,2 A, calculam-se 0,2 V e 0,04 W no resistor. Esses são cálculos nominais, não resultados medidos. A tolerância de 5% e a exatidão do ADC afetam a medida. Módulos CC/CV podem medir corrente no retorno: não unir IN− e OUT− externamente sem verificar o circuito, pois isso pode desviar o resistor de medição do regulador.
... A24: Fonte técnica — Coherent | B24: Thermoelectric Cooling Systems Design Guide: dimensionamento, dissipação, alimentação DC, ondulação, controle e montagem de TECs. https://www.coherent.com/resources/datasheet/materials/related-resources/thermoelectrics/thermoelectric-cooling-systems-design-guide-br.pdf
A25: Rastreabilidade do projeto
